[36m[2023-08-29 14:01:44 DEBUG] [cli:114][39m ###############################################################################
[36m[2023-08-29 14:01:44 DEBUG] [cli:115][39m Running command 'validate'
[36m[2023-08-29 14:01:44 DEBUG] [cli:119][39m Using settings file '/Users/collinsorighose/.chaostoolkit/settings.yaml'
[36m[2023-08-29 14:07:57 DEBUG] [cli:114][39m ###############################################################################
[36m[2023-08-29 14:07:57 DEBUG] [cli:115][39m Running command 'validate'
[36m[2023-08-29 14:07:57 DEBUG] [cli:119][39m Using settings file '/Users/collinsorighose/.chaostoolkit/settings.yaml'
[36m[2023-08-29 14:07:57 DEBUG] [settings:30][39m The Chaos Toolkit settings file could not be found at '/Users/collinsorighose/.chaostoolkit/settings.yaml'.
[36m[2023-08-29 14:07:57 DEBUG] [__init__:450][39m No controls to apply on 'loader'
[36m[2023-08-29 14:07:57 DEBUG] [__init__:450][39m No controls to apply on 'loader'
[36m[2023-08-29 14:07:57 DEBUG] [caching:24][39m Building activity cache...
[36m[2023-08-29 14:07:57 DEBUG] [caching:35][39m Cached 1 activities
[32m[2023-08-29 14:07:57 INFO] [experiment:58][39m Validating the experiment's syntax
[36m[2023-08-29 14:07:57 DEBUG] [configuration:63][39m Loading configuration...
[36m[2023-08-29 14:07:57 DEBUG] [secret:78][39m Loading secrets...
[36m[2023-08-29 14:07:57 DEBUG] [secret:103][39m Done loading secrets
[32m[2023-08-29 14:07:57 INFO] [experiment:109][39m Experiment looks valid
[36m[2023-08-29 14:07:57 DEBUG] [caching:42][39m Clearing activities cache
[32m[2023-08-29 14:07:57 INFO] [cli:374][39m experiment syntax and semantic look valid
[36m[2023-08-29 14:08:13 DEBUG] [cli:114][39m ###############################################################################
[36m[2023-08-29 14:08:13 DEBUG] [cli:115][39m Running command 'run'
[36m[2023-08-29 14:08:13 DEBUG] [cli:119][39m Using settings file '/Users/collinsorighose/.chaostoolkit/settings.yaml'
[36m[2023-08-29 14:08:15 DEBUG] [settings:30][39m The Chaos Toolkit settings file could not be found at '/Users/collinsorighose/.chaostoolkit/settings.yaml'.
[36m[2023-08-29 14:08:15 DEBUG] [__init__:450][39m No controls to apply on 'loader'
[36m[2023-08-29 14:08:15 DEBUG] [__init__:450][39m No controls to apply on 'loader'
[36m[2023-08-29 14:08:15 DEBUG] [caching:24][39m Building activity cache...
[36m[2023-08-29 14:08:15 DEBUG] [caching:35][39m Cached 1 activities
[32m[2023-08-29 14:08:15 INFO] [experiment:58][39m Validating the experiment's syntax
[36m[2023-08-29 14:08:15 DEBUG] [configuration:63][39m Loading configuration...
[36m[2023-08-29 14:08:15 DEBUG] [secret:78][39m Loading secrets...
[36m[2023-08-29 14:08:15 DEBUG] [secret:103][39m Done loading secrets
[32m[2023-08-29 14:08:15 INFO] [experiment:109][39m Experiment looks valid
[36m[2023-08-29 14:08:15 DEBUG] [caching:42][39m Clearing activities cache
[36m[2023-08-29 14:08:15 DEBUG] [cli:314][39m Runtime strategies: hypothesis - default / rollbacks - default
[36m[2023-08-29 14:08:15 DEBUG] [caching:24][39m Building activity cache...
[36m[2023-08-29 14:08:15 DEBUG] [caching:35][39m Cached 1 activities
[36m[2023-08-29 14:08:15 DEBUG] [configuration:63][39m Loading configuration...
[36m[2023-08-29 14:08:15 DEBUG] [secret:78][39m Loading secrets...
[36m[2023-08-29 14:08:15 DEBUG] [secret:103][39m Done loading secrets
[36m[2023-08-29 14:08:15 DEBUG] [configuration:160][39m Loading dynamic configuration...
[32m[2023-08-29 14:08:15 INFO] [run:369][39m Running experiment: create SSM document
[36m[2023-08-29 14:08:15 DEBUG] [__init__:64][39m Initializing controls
[32m[2023-08-29 14:08:15 INFO] [run:396][39m Steady-state strategy: default
[32m[2023-08-29 14:08:15 INFO] [run:400][39m Rollbacks strategy: default
[32m[2023-08-29 14:08:15 INFO] [run:408][39m No steady state hypothesis defined. That's ok, just exploring.
[36m[2023-08-29 14:08:15 DEBUG] [__init__:450][39m No controls to apply on 'experiment'
[32m[2023-08-29 14:08:15 INFO] [run:684][39m Playing your experiment's method now...
[36m[2023-08-29 14:08:15 DEBUG] [__init__:450][39m No controls to apply on 'method'
[36m[2023-08-29 14:08:15 DEBUG] [__init__:450][39m No controls to apply on 'activity'
[32m[2023-08-29 14:08:15 INFO] [activity:215][39m Action: create-document
[36m[2023-08-29 14:08:15 DEBUG] [python:33][39m Activity 'create-document' loaded from '/Users/collinsorighose/opt/anaconda3/envs/demo/lib/python3.11/site-packages/chaosaws/ssm/actions.py'
[36m[2023-08-29 14:08:15 DEBUG] [__init__:76][39m Using AWS region 'eu-west-2'
[36m[2023-08-29 14:08:15 DEBUG] [__init__:85][39m Client will be using profile 'default' from boto3 session
[36m[2023-08-29 14:08:16 DEBUG] [activity:294][39m Activity failed
    Traceback (most recent call last):
      File "/Users/collinsorighose/opt/anaconda3/envs/demo/lib/python3.11/site-packages/chaoslib/provider/python.py", line 56, in run_python_activity
        return func(**arguments)
               ^^^^^^^^^^^^^^^^^
      File "/Users/collinsorighose/opt/anaconda3/envs/demo/lib/python3.11/site-packages/chaosaws/ssm/actions.py", line 39, in create_document
        return client.create_document(
               ^^^^^^^^^^^^^^^^^^^^^^^
      File "/Users/collinsorighose/opt/anaconda3/envs/demo/lib/python3.11/site-packages/botocore/client.py", line 530, in _api_call
        return self._make_api_call(operation_name, kwargs)
               ^^^^^^^^^^^^^^^^^^^^^^^^^^^^^^^^^^^^^^^^^^^
      File "/Users/collinsorighose/opt/anaconda3/envs/demo/lib/python3.11/site-packages/botocore/client.py", line 919, in _make_api_call
        request_dict = self._convert_to_request_dict(
                       ^^^^^^^^^^^^^^^^^^^^^^^^^^^^^^
      File "/Users/collinsorighose/opt/anaconda3/envs/demo/lib/python3.11/site-packages/botocore/client.py", line 990, in _convert_to_request_dict
        request_dict = self._serializer.serialize_to_request(
                       ^^^^^^^^^^^^^^^^^^^^^^^^^^^^^^^^^^^^^^
      File "/Users/collinsorighose/opt/anaconda3/envs/demo/lib/python3.11/site-packages/botocore/validate.py", line 381, in serialize_to_request
        raise ParamValidationError(report=report.generate_report())
    botocore.exceptions.ParamValidationError: Parameter validation failed:
    Invalid type for parameter VersionName, value: None, type: <class 'NoneType'>, valid types: <class 'str'>
    Invalid type for parameter DocumentType, value: None, type: <class 'NoneType'>, valid types: <class 'str'>
    Invalid type for parameter DocumentFormat, value: None, type: <class 'NoneType'>, valid types: <class 'str'>
    
    During handling of the above exception, another exception occurred:
    
    Traceback (most recent call last):
      File "/Users/collinsorighose/opt/anaconda3/envs/demo/lib/python3.11/site-packages/chaoslib/activity.py", line 287, in run_activity
        result = run_python_activity(activity, configuration, secrets)
                 ^^^^^^^^^^^^^^^^^^^^^^^^^^^^^^^^^^^^^^^^^^^^^^^^^^^^^
      File "/Users/collinsorighose/opt/anaconda3/envs/demo/lib/python3.11/site-packages/chaoslib/provider/python.py", line 58, in run_python_activity
        raise ActivityFailed(
      File "/Users/collinsorighose/opt/anaconda3/envs/demo/lib/python3.11/site-packages/chaoslib/provider/python.py", line 56, in run_python_activity
        return func(**arguments)
               ^^^^^^^^^^^^^^^^^
      File "/Users/collinsorighose/opt/anaconda3/envs/demo/lib/python3.11/site-packages/chaosaws/ssm/actions.py", line 39, in create_document
        return client.create_document(
               ^^^^^^^^^^^^^^^^^^^^^^^
      File "/Users/collinsorighose/opt/anaconda3/envs/demo/lib/python3.11/site-packages/botocore/client.py", line 530, in _api_call
        return self._make_api_call(operation_name, kwargs)
               ^^^^^^^^^^^^^^^^^^^^^^^^^^^^^^^^^^^^^^^^^^^
      File "/Users/collinsorighose/opt/anaconda3/envs/demo/lib/python3.11/site-packages/botocore/client.py", line 919, in _make_api_call
        request_dict = self._convert_to_request_dict(
                       ^^^^^^^^^^^^^^^^^^^^^^^^^^^^^^
      File "/Users/collinsorighose/opt/anaconda3/envs/demo/lib/python3.11/site-packages/botocore/client.py", line 990, in _convert_to_request_dict
        request_dict = self._serializer.serialize_to_request(
                       ^^^^^^^^^^^^^^^^^^^^^^^^^^^^^^^^^^^^^^
      File "/Users/collinsorighose/opt/anaconda3/envs/demo/lib/python3.11/site-packages/botocore/validate.py", line 381, in serialize_to_request
        raise ParamValidationError(report=report.generate_report())
    chaoslib.exceptions.ActivityFailed: botocore.exceptions.ParamValidationError: Parameter validation failed:
    Invalid type for parameter VersionName, value: None, type: <class 'NoneType'>, valid types: <class 'str'>
    Invalid type for parameter DocumentType, value: None, type: <class 'NoneType'>, valid types: <class 'str'>
    Invalid type for parameter DocumentFormat, value: None, type: <class 'NoneType'>, valid types: <class 'str'>
[31m[2023-08-29 14:08:16 ERROR] [activity:245][39m   => failed: botocore.exceptions.ParamValidationError: Parameter validation failed:
    Invalid type for parameter VersionName, value: None, type: <class 'NoneType'>, valid types: <class 'str'>
    Invalid type for parameter DocumentType, value: None, type: <class 'NoneType'>, valid types: <class 'str'>
    Invalid type for parameter DocumentFormat, value: None, type: <class 'NoneType'>, valid types: <class 'str'>
[36m[2023-08-29 14:08:16 DEBUG] [__init__:450][39m No controls to apply on 'activity'
[36m[2023-08-29 14:08:16 DEBUG] [__init__:450][39m No controls to apply on 'method'
[32m[2023-08-29 14:08:16 INFO] [run:964][39m Let's rollback...
[36m[2023-08-29 14:08:16 DEBUG] [__init__:450][39m No controls to apply on 'rollback'
[32m[2023-08-29 14:08:16 INFO] [rollback:31][39m No declared rollbacks, let's move on.
[36m[2023-08-29 14:08:16 DEBUG] [__init__:450][39m No controls to apply on 'rollback'
[32m[2023-08-29 14:08:16 INFO] [run:515][39m Experiment ended with status: completed
[36m[2023-08-29 14:08:16 DEBUG] [__init__:450][39m No controls to apply on 'experiment'
[36m[2023-08-29 14:08:16 DEBUG] [__init__:103][39m Cleaning up controls
[36m[2023-08-29 14:08:16 DEBUG] [caching:42][39m Clearing activities cache
[36m[2023-08-29 14:11:07 DEBUG] [cli:114][39m ###############################################################################
[36m[2023-08-29 14:11:07 DEBUG] [cli:115][39m Running command 'run'
[36m[2023-08-29 14:11:07 DEBUG] [cli:119][39m Using settings file '/Users/collinsorighose/.chaostoolkit/settings.yaml'
[36m[2023-08-29 14:11:08 DEBUG] [settings:30][39m The Chaos Toolkit settings file could not be found at '/Users/collinsorighose/.chaostoolkit/settings.yaml'.
[36m[2023-08-29 14:11:08 DEBUG] [__init__:450][39m No controls to apply on 'loader'
[36m[2023-08-29 14:11:08 DEBUG] [__init__:450][39m No controls to apply on 'loader'
[31m[2023-08-29 14:11:08 ERROR] [cli:268][39m Path "create-doc.json" does not exist.
[36m[2023-08-29 14:11:08 DEBUG] [cli:269][39m Path "create-doc.json" does not exist.
[36m[2023-08-29 14:11:37 DEBUG] [cli:114][39m ###############################################################################
[36m[2023-08-29 14:11:37 DEBUG] [cli:115][39m Running command 'run'
[36m[2023-08-29 14:11:37 DEBUG] [cli:119][39m Using settings file '/Users/collinsorighose/.chaostoolkit/settings.yaml'
[36m[2023-08-29 14:11:38 DEBUG] [settings:30][39m The Chaos Toolkit settings file could not be found at '/Users/collinsorighose/.chaostoolkit/settings.yaml'.
[36m[2023-08-29 14:11:38 DEBUG] [__init__:450][39m No controls to apply on 'loader'
[36m[2023-08-29 14:11:38 DEBUG] [__init__:450][39m No controls to apply on 'loader'
[36m[2023-08-29 14:11:38 DEBUG] [caching:24][39m Building activity cache...
[36m[2023-08-29 14:11:38 DEBUG] [caching:35][39m Cached 1 activities
[32m[2023-08-29 14:11:38 INFO] [experiment:58][39m Validating the experiment's syntax
[36m[2023-08-29 14:11:38 DEBUG] [configuration:63][39m Loading configuration...
[36m[2023-08-29 14:11:38 DEBUG] [secret:78][39m Loading secrets...
[36m[2023-08-29 14:11:38 DEBUG] [secret:103][39m Done loading secrets
[32m[2023-08-29 14:11:38 INFO] [experiment:109][39m Experiment looks valid
[36m[2023-08-29 14:11:38 DEBUG] [caching:42][39m Clearing activities cache
[36m[2023-08-29 14:11:38 DEBUG] [cli:314][39m Runtime strategies: hypothesis - default / rollbacks - default
[36m[2023-08-29 14:11:38 DEBUG] [caching:24][39m Building activity cache...
[36m[2023-08-29 14:11:38 DEBUG] [caching:35][39m Cached 1 activities
[36m[2023-08-29 14:11:38 DEBUG] [configuration:63][39m Loading configuration...
[36m[2023-08-29 14:11:38 DEBUG] [secret:78][39m Loading secrets...
[36m[2023-08-29 14:11:38 DEBUG] [secret:103][39m Done loading secrets
[36m[2023-08-29 14:11:38 DEBUG] [configuration:160][39m Loading dynamic configuration...
[32m[2023-08-29 14:11:38 INFO] [run:369][39m Running experiment: create SSM document
[36m[2023-08-29 14:11:38 DEBUG] [__init__:64][39m Initializing controls
[32m[2023-08-29 14:11:38 INFO] [run:396][39m Steady-state strategy: default
[32m[2023-08-29 14:11:38 INFO] [run:400][39m Rollbacks strategy: default
[32m[2023-08-29 14:11:38 INFO] [run:408][39m No steady state hypothesis defined. That's ok, just exploring.
[36m[2023-08-29 14:11:38 DEBUG] [__init__:450][39m No controls to apply on 'experiment'
[32m[2023-08-29 14:11:38 INFO] [run:684][39m Playing your experiment's method now...
[36m[2023-08-29 14:11:38 DEBUG] [__init__:450][39m No controls to apply on 'method'
[36m[2023-08-29 14:11:38 DEBUG] [__init__:450][39m No controls to apply on 'activity'
[32m[2023-08-29 14:11:38 INFO] [activity:215][39m Action: create-document
[36m[2023-08-29 14:11:38 DEBUG] [python:33][39m Activity 'create-document' loaded from '/Users/collinsorighose/opt/anaconda3/envs/demo/lib/python3.11/site-packages/chaosaws/ssm/actions.py'
[36m[2023-08-29 14:11:38 DEBUG] [activity:294][39m Activity failed
    Traceback (most recent call last):
      File "/Users/collinsorighose/opt/anaconda3/envs/demo/lib/python3.11/site-packages/chaoslib/provider/python.py", line 56, in run_python_activity
        return func(**arguments)
               ^^^^^^^^^^^^^^^^^
      File "/Users/collinsorighose/opt/anaconda3/envs/demo/lib/python3.11/site-packages/chaosaws/ssm/actions.py", line 36, in create_document
        with open(path_content) as open_file:
             ^^^^^^^^^^^^^^^^^^
    FileNotFoundError: [Errno 2] No such file or directory: './test-doc.txt'
    
    During handling of the above exception, another exception occurred:
    
    Traceback (most recent call last):
      File "/Users/collinsorighose/opt/anaconda3/envs/demo/lib/python3.11/site-packages/chaoslib/activity.py", line 287, in run_activity
        result = run_python_activity(activity, configuration, secrets)
                 ^^^^^^^^^^^^^^^^^^^^^^^^^^^^^^^^^^^^^^^^^^^^^^^^^^^^^
      File "/Users/collinsorighose/opt/anaconda3/envs/demo/lib/python3.11/site-packages/chaoslib/provider/python.py", line 58, in run_python_activity
        raise ActivityFailed(
      File "/Users/collinsorighose/opt/anaconda3/envs/demo/lib/python3.11/site-packages/chaoslib/provider/python.py", line 56, in run_python_activity
        return func(**arguments)
               ^^^^^^^^^^^^^^^^^
      File "/Users/collinsorighose/opt/anaconda3/envs/demo/lib/python3.11/site-packages/chaosaws/ssm/actions.py", line 36, in create_document
        with open(path_content) as open_file:
             ^^^^^^^^^^^^^^^^^^
    chaoslib.exceptions.ActivityFailed: FileNotFoundError: [Errno 2] No such file or directory: './test-doc.txt'
[31m[2023-08-29 14:11:38 ERROR] [activity:245][39m   => failed: FileNotFoundError: [Errno 2] No such file or directory: './test-doc.txt'
[36m[2023-08-29 14:11:38 DEBUG] [__init__:450][39m No controls to apply on 'activity'
[36m[2023-08-29 14:11:38 DEBUG] [__init__:450][39m No controls to apply on 'method'
[32m[2023-08-29 14:11:38 INFO] [run:964][39m Let's rollback...
[36m[2023-08-29 14:11:38 DEBUG] [__init__:450][39m No controls to apply on 'rollback'
[32m[2023-08-29 14:11:38 INFO] [rollback:31][39m No declared rollbacks, let's move on.
[36m[2023-08-29 14:11:38 DEBUG] [__init__:450][39m No controls to apply on 'rollback'
[32m[2023-08-29 14:11:38 INFO] [run:515][39m Experiment ended with status: completed
[36m[2023-08-29 14:11:38 DEBUG] [__init__:450][39m No controls to apply on 'experiment'
[36m[2023-08-29 14:11:38 DEBUG] [__init__:103][39m Cleaning up controls
[36m[2023-08-29 14:11:38 DEBUG] [caching:42][39m Clearing activities cache
[36m[2023-08-29 14:12:05 DEBUG] [cli:114][39m ###############################################################################
[36m[2023-08-29 14:12:05 DEBUG] [cli:115][39m Running command 'run'
[36m[2023-08-29 14:12:05 DEBUG] [cli:119][39m Using settings file '/Users/collinsorighose/.chaostoolkit/settings.yaml'
[36m[2023-08-29 14:12:06 DEBUG] [settings:30][39m The Chaos Toolkit settings file could not be found at '/Users/collinsorighose/.chaostoolkit/settings.yaml'.
[36m[2023-08-29 14:12:06 DEBUG] [__init__:450][39m No controls to apply on 'loader'
[36m[2023-08-29 14:12:06 DEBUG] [__init__:450][39m No controls to apply on 'loader'
[36m[2023-08-29 14:12:06 DEBUG] [caching:24][39m Building activity cache...
[36m[2023-08-29 14:12:06 DEBUG] [caching:35][39m Cached 1 activities
[32m[2023-08-29 14:12:06 INFO] [experiment:58][39m Validating the experiment's syntax
[36m[2023-08-29 14:12:06 DEBUG] [configuration:63][39m Loading configuration...
[36m[2023-08-29 14:12:06 DEBUG] [secret:78][39m Loading secrets...
[36m[2023-08-29 14:12:06 DEBUG] [secret:103][39m Done loading secrets
[32m[2023-08-29 14:12:06 INFO] [experiment:109][39m Experiment looks valid
[36m[2023-08-29 14:12:06 DEBUG] [caching:42][39m Clearing activities cache
[36m[2023-08-29 14:12:06 DEBUG] [cli:314][39m Runtime strategies: hypothesis - default / rollbacks - default
[36m[2023-08-29 14:12:06 DEBUG] [caching:24][39m Building activity cache...
[36m[2023-08-29 14:12:06 DEBUG] [caching:35][39m Cached 1 activities
[36m[2023-08-29 14:12:06 DEBUG] [configuration:63][39m Loading configuration...
[36m[2023-08-29 14:12:06 DEBUG] [secret:78][39m Loading secrets...
[36m[2023-08-29 14:12:06 DEBUG] [secret:103][39m Done loading secrets
[36m[2023-08-29 14:12:06 DEBUG] [configuration:160][39m Loading dynamic configuration...
[32m[2023-08-29 14:12:06 INFO] [run:369][39m Running experiment: create SSM document
[36m[2023-08-29 14:12:06 DEBUG] [__init__:64][39m Initializing controls
[32m[2023-08-29 14:12:06 INFO] [run:396][39m Steady-state strategy: default
[32m[2023-08-29 14:12:06 INFO] [run:400][39m Rollbacks strategy: default
[32m[2023-08-29 14:12:06 INFO] [run:408][39m No steady state hypothesis defined. That's ok, just exploring.
[36m[2023-08-29 14:12:06 DEBUG] [__init__:450][39m No controls to apply on 'experiment'
[32m[2023-08-29 14:12:06 INFO] [run:684][39m Playing your experiment's method now...
[36m[2023-08-29 14:12:06 DEBUG] [__init__:450][39m No controls to apply on 'method'
[36m[2023-08-29 14:12:06 DEBUG] [__init__:450][39m No controls to apply on 'activity'
[32m[2023-08-29 14:12:06 INFO] [activity:215][39m Action: create-document
[36m[2023-08-29 14:12:06 DEBUG] [python:33][39m Activity 'create-document' loaded from '/Users/collinsorighose/opt/anaconda3/envs/demo/lib/python3.11/site-packages/chaosaws/ssm/actions.py'
[36m[2023-08-29 14:12:06 DEBUG] [__init__:76][39m Using AWS region 'eu-west-2'
[36m[2023-08-29 14:12:06 DEBUG] [__init__:85][39m Client will be using profile 'default' from boto3 session
[36m[2023-08-29 14:12:12 DEBUG] [activity:294][39m Activity failed
    Traceback (most recent call last):
      File "/Users/collinsorighose/opt/anaconda3/envs/demo/lib/python3.11/site-packages/chaoslib/provider/python.py", line 56, in run_python_activity
        return func(**arguments)
               ^^^^^^^^^^^^^^^^^
      File "/Users/collinsorighose/opt/anaconda3/envs/demo/lib/python3.11/site-packages/chaosaws/ssm/actions.py", line 39, in create_document
        return client.create_document(
               ^^^^^^^^^^^^^^^^^^^^^^^
      File "/Users/collinsorighose/opt/anaconda3/envs/demo/lib/python3.11/site-packages/botocore/client.py", line 530, in _api_call
        return self._make_api_call(operation_name, kwargs)
               ^^^^^^^^^^^^^^^^^^^^^^^^^^^^^^^^^^^^^^^^^^^
      File "/Users/collinsorighose/opt/anaconda3/envs/demo/lib/python3.11/site-packages/botocore/client.py", line 919, in _make_api_call
        request_dict = self._convert_to_request_dict(
                       ^^^^^^^^^^^^^^^^^^^^^^^^^^^^^^
      File "/Users/collinsorighose/opt/anaconda3/envs/demo/lib/python3.11/site-packages/botocore/client.py", line 990, in _convert_to_request_dict
        request_dict = self._serializer.serialize_to_request(
                       ^^^^^^^^^^^^^^^^^^^^^^^^^^^^^^^^^^^^^^
      File "/Users/collinsorighose/opt/anaconda3/envs/demo/lib/python3.11/site-packages/botocore/validate.py", line 381, in serialize_to_request
        raise ParamValidationError(report=report.generate_report())
    botocore.exceptions.ParamValidationError: Parameter validation failed:
    Invalid type for parameter VersionName, value: None, type: <class 'NoneType'>, valid types: <class 'str'>
    Invalid type for parameter DocumentType, value: None, type: <class 'NoneType'>, valid types: <class 'str'>
    Invalid type for parameter DocumentFormat, value: None, type: <class 'NoneType'>, valid types: <class 'str'>
    
    During handling of the above exception, another exception occurred:
    
    Traceback (most recent call last):
      File "/Users/collinsorighose/opt/anaconda3/envs/demo/lib/python3.11/site-packages/chaoslib/activity.py", line 287, in run_activity
        result = run_python_activity(activity, configuration, secrets)
                 ^^^^^^^^^^^^^^^^^^^^^^^^^^^^^^^^^^^^^^^^^^^^^^^^^^^^^
      File "/Users/collinsorighose/opt/anaconda3/envs/demo/lib/python3.11/site-packages/chaoslib/provider/python.py", line 58, in run_python_activity
        raise ActivityFailed(
      File "/Users/collinsorighose/opt/anaconda3/envs/demo/lib/python3.11/site-packages/chaoslib/provider/python.py", line 56, in run_python_activity
        return func(**arguments)
               ^^^^^^^^^^^^^^^^^
      File "/Users/collinsorighose/opt/anaconda3/envs/demo/lib/python3.11/site-packages/chaosaws/ssm/actions.py", line 39, in create_document
        return client.create_document(
               ^^^^^^^^^^^^^^^^^^^^^^^
      File "/Users/collinsorighose/opt/anaconda3/envs/demo/lib/python3.11/site-packages/botocore/client.py", line 530, in _api_call
        return self._make_api_call(operation_name, kwargs)
               ^^^^^^^^^^^^^^^^^^^^^^^^^^^^^^^^^^^^^^^^^^^
      File "/Users/collinsorighose/opt/anaconda3/envs/demo/lib/python3.11/site-packages/botocore/client.py", line 919, in _make_api_call
        request_dict = self._convert_to_request_dict(
                       ^^^^^^^^^^^^^^^^^^^^^^^^^^^^^^
      File "/Users/collinsorighose/opt/anaconda3/envs/demo/lib/python3.11/site-packages/botocore/client.py", line 990, in _convert_to_request_dict
        request_dict = self._serializer.serialize_to_request(
                       ^^^^^^^^^^^^^^^^^^^^^^^^^^^^^^^^^^^^^^
      File "/Users/collinsorighose/opt/anaconda3/envs/demo/lib/python3.11/site-packages/botocore/validate.py", line 381, in serialize_to_request
        raise ParamValidationError(report=report.generate_report())
    chaoslib.exceptions.ActivityFailed: botocore.exceptions.ParamValidationError: Parameter validation failed:
    Invalid type for parameter VersionName, value: None, type: <class 'NoneType'>, valid types: <class 'str'>
    Invalid type for parameter DocumentType, value: None, type: <class 'NoneType'>, valid types: <class 'str'>
    Invalid type for parameter DocumentFormat, value: None, type: <class 'NoneType'>, valid types: <class 'str'>
[31m[2023-08-29 14:12:12 ERROR] [activity:245][39m   => failed: botocore.exceptions.ParamValidationError: Parameter validation failed:
    Invalid type for parameter VersionName, value: None, type: <class 'NoneType'>, valid types: <class 'str'>
    Invalid type for parameter DocumentType, value: None, type: <class 'NoneType'>, valid types: <class 'str'>
    Invalid type for parameter DocumentFormat, value: None, type: <class 'NoneType'>, valid types: <class 'str'>
[36m[2023-08-29 14:12:12 DEBUG] [__init__:450][39m No controls to apply on 'activity'
[36m[2023-08-29 14:12:12 DEBUG] [__init__:450][39m No controls to apply on 'method'
[32m[2023-08-29 14:12:12 INFO] [run:964][39m Let's rollback...
[36m[2023-08-29 14:12:12 DEBUG] [__init__:450][39m No controls to apply on 'rollback'
[32m[2023-08-29 14:12:12 INFO] [rollback:31][39m No declared rollbacks, let's move on.
[36m[2023-08-29 14:12:12 DEBUG] [__init__:450][39m No controls to apply on 'rollback'
[32m[2023-08-29 14:12:12 INFO] [run:515][39m Experiment ended with status: completed
[36m[2023-08-29 14:12:12 DEBUG] [__init__:450][39m No controls to apply on 'experiment'
[36m[2023-08-29 14:12:12 DEBUG] [__init__:103][39m Cleaning up controls
[36m[2023-08-29 14:12:12 DEBUG] [caching:42][39m Clearing activities cache
[36m[2023-08-29 14:15:42 DEBUG] [cli:114][39m ###############################################################################
[36m[2023-08-29 14:15:42 DEBUG] [cli:115][39m Running command 'run'
[36m[2023-08-29 14:15:42 DEBUG] [cli:119][39m Using settings file '/Users/collinsorighose/.chaostoolkit/settings.yaml'
[36m[2023-08-29 14:15:43 DEBUG] [settings:30][39m The Chaos Toolkit settings file could not be found at '/Users/collinsorighose/.chaostoolkit/settings.yaml'.
[36m[2023-08-29 14:15:43 DEBUG] [__init__:450][39m No controls to apply on 'loader'
[36m[2023-08-29 14:15:43 DEBUG] [__init__:450][39m No controls to apply on 'loader'
[36m[2023-08-29 14:15:43 DEBUG] [caching:24][39m Building activity cache...
[36m[2023-08-29 14:15:43 DEBUG] [caching:35][39m Cached 1 activities
[32m[2023-08-29 14:15:43 INFO] [experiment:58][39m Validating the experiment's syntax
[36m[2023-08-29 14:15:43 DEBUG] [configuration:63][39m Loading configuration...
[36m[2023-08-29 14:15:43 DEBUG] [secret:78][39m Loading secrets...
[36m[2023-08-29 14:15:43 DEBUG] [secret:103][39m Done loading secrets
[32m[2023-08-29 14:15:43 INFO] [experiment:109][39m Experiment looks valid
[36m[2023-08-29 14:15:43 DEBUG] [caching:42][39m Clearing activities cache
[36m[2023-08-29 14:15:43 DEBUG] [cli:314][39m Runtime strategies: hypothesis - default / rollbacks - default
[36m[2023-08-29 14:15:43 DEBUG] [caching:24][39m Building activity cache...
[36m[2023-08-29 14:15:43 DEBUG] [caching:35][39m Cached 1 activities
[36m[2023-08-29 14:15:43 DEBUG] [configuration:63][39m Loading configuration...
[36m[2023-08-29 14:15:43 DEBUG] [secret:78][39m Loading secrets...
[36m[2023-08-29 14:15:43 DEBUG] [secret:103][39m Done loading secrets
[36m[2023-08-29 14:15:43 DEBUG] [configuration:160][39m Loading dynamic configuration...
[32m[2023-08-29 14:15:43 INFO] [run:369][39m Running experiment: create SSM document
[36m[2023-08-29 14:15:43 DEBUG] [__init__:64][39m Initializing controls
[32m[2023-08-29 14:15:43 INFO] [run:396][39m Steady-state strategy: default
[32m[2023-08-29 14:15:43 INFO] [run:400][39m Rollbacks strategy: default
[32m[2023-08-29 14:15:43 INFO] [run:408][39m No steady state hypothesis defined. That's ok, just exploring.
[36m[2023-08-29 14:15:43 DEBUG] [__init__:450][39m No controls to apply on 'experiment'
[32m[2023-08-29 14:15:43 INFO] [run:684][39m Playing your experiment's method now...
[36m[2023-08-29 14:15:43 DEBUG] [__init__:450][39m No controls to apply on 'method'
[36m[2023-08-29 14:15:43 DEBUG] [__init__:450][39m No controls to apply on 'activity'
[32m[2023-08-29 14:15:43 INFO] [activity:215][39m Action: create-document
[36m[2023-08-29 14:15:43 DEBUG] [python:33][39m Activity 'create-document' loaded from '/Users/collinsorighose/opt/anaconda3/envs/demo/lib/python3.11/site-packages/chaosaws/ssm/actions.py'
[36m[2023-08-29 14:15:43 DEBUG] [__init__:76][39m Using AWS region 'eu-west-2'
[36m[2023-08-29 14:15:43 DEBUG] [__init__:85][39m Client will be using profile 'default' from boto3 session
[36m[2023-08-29 14:15:47 DEBUG] [activity:294][39m Activity failed
    Traceback (most recent call last):
      File "/Users/collinsorighose/opt/anaconda3/envs/demo/lib/python3.11/site-packages/chaosaws/ssm/actions.py", line 39, in create_document
        return client.create_document(
               ^^^^^^^^^^^^^^^^^^^^^^^
      File "/Users/collinsorighose/opt/anaconda3/envs/demo/lib/python3.11/site-packages/botocore/client.py", line 530, in _api_call
        return self._make_api_call(operation_name, kwargs)
               ^^^^^^^^^^^^^^^^^^^^^^^^^^^^^^^^^^^^^^^^^^^
      File "/Users/collinsorighose/opt/anaconda3/envs/demo/lib/python3.11/site-packages/botocore/client.py", line 960, in _make_api_call
        raise error_class(parsed_response, operation_name)
    botocore.exceptions.ClientError: An error occurred (ValidationException) when calling the CreateDocument operation: 3 validation errors detected: Value at 'documentType' failed to satisfy constraint: Member is not a valid documentType; Value at 'versionName' failed to satisfy constraint: Member must satisfy regular expression pattern: ^[a-zA-Z0-9_\-.]{1,128}$; Value at 'documentFormat' failed to satisfy constraint: Member must satisfy enum value set: [YAML, JSON, TEXT]
    
    During handling of the above exception, another exception occurred:
    
    Traceback (most recent call last):
      File "/Users/collinsorighose/opt/anaconda3/envs/demo/lib/python3.11/site-packages/chaoslib/provider/python.py", line 56, in run_python_activity
        return func(**arguments)
               ^^^^^^^^^^^^^^^^^
      File "/Users/collinsorighose/opt/anaconda3/envs/demo/lib/python3.11/site-packages/chaosaws/ssm/actions.py", line 47, in create_document
        raise ActivityFailed(
    chaoslib.exceptions.ActivityFailed: Failed to create document 'chaos-ssm-doc': '3 validation errors detected: Value at 'documentType' failed to satisfy constraint: Member is not a valid documentType; Value at 'versionName' failed to satisfy constraint: Member must satisfy regular expression pattern: ^[a-zA-Z0-9_\-.]{1,128}$; Value at 'documentFormat' failed to satisfy constraint: Member must satisfy enum value set: [YAML, JSON, TEXT]'
    
    During handling of the above exception, another exception occurred:
    
    Traceback (most recent call last):
      File "/Users/collinsorighose/opt/anaconda3/envs/demo/lib/python3.11/site-packages/chaoslib/activity.py", line 287, in run_activity
        result = run_python_activity(activity, configuration, secrets)
                 ^^^^^^^^^^^^^^^^^^^^^^^^^^^^^^^^^^^^^^^^^^^^^^^^^^^^^
      File "/Users/collinsorighose/opt/anaconda3/envs/demo/lib/python3.11/site-packages/chaoslib/provider/python.py", line 58, in run_python_activity
        raise ActivityFailed(
      File "/Users/collinsorighose/opt/anaconda3/envs/demo/lib/python3.11/site-packages/chaoslib/provider/python.py", line 56, in run_python_activity
        return func(**arguments)
               ^^^^^^^^^^^^^^^^^
      File "/Users/collinsorighose/opt/anaconda3/envs/demo/lib/python3.11/site-packages/chaosaws/ssm/actions.py", line 47, in create_document
        raise ActivityFailed(
    chaoslib.exceptions.ActivityFailed: chaoslib.exceptions.ActivityFailed: Failed to create document 'chaos-ssm-doc': '3 validation errors detected: Value at 'documentType' failed to satisfy constraint: Member is not a valid documentType; Value at 'versionName' failed to satisfy constraint: Member must satisfy regular expression pattern: ^[a-zA-Z0-9_\-.]{1,128}$; Value at 'documentFormat' failed to satisfy constraint: Member must satisfy enum value set: [YAML, JSON, TEXT]'
[31m[2023-08-29 14:15:47 ERROR] [activity:245][39m   => failed: chaoslib.exceptions.ActivityFailed: Failed to create document 'chaos-ssm-doc': '3 validation errors detected: Value at 'documentType' failed to satisfy constraint: Member is not a valid documentType; Value at 'versionName' failed to satisfy constraint: Member must satisfy regular expression pattern: ^[a-zA-Z0-9_\-.]{1,128}$; Value at 'documentFormat' failed to satisfy constraint: Member must satisfy enum value set: [YAML, JSON, TEXT]'
[36m[2023-08-29 14:15:47 DEBUG] [__init__:450][39m No controls to apply on 'activity'
[36m[2023-08-29 14:15:47 DEBUG] [__init__:450][39m No controls to apply on 'method'
[32m[2023-08-29 14:15:47 INFO] [run:964][39m Let's rollback...
[36m[2023-08-29 14:15:47 DEBUG] [__init__:450][39m No controls to apply on 'rollback'
[32m[2023-08-29 14:15:47 INFO] [rollback:31][39m No declared rollbacks, let's move on.
[36m[2023-08-29 14:15:47 DEBUG] [__init__:450][39m No controls to apply on 'rollback'
[32m[2023-08-29 14:15:47 INFO] [run:515][39m Experiment ended with status: completed
[36m[2023-08-29 14:15:47 DEBUG] [__init__:450][39m No controls to apply on 'experiment'
[36m[2023-08-29 14:15:47 DEBUG] [__init__:103][39m Cleaning up controls
[36m[2023-08-29 14:15:47 DEBUG] [caching:42][39m Clearing activities cache
[36m[2023-08-29 15:35:45 DEBUG] [cli:114][39m ###############################################################################
[36m[2023-08-29 15:35:45 DEBUG] [cli:115][39m Running command 'run'
[36m[2023-08-29 15:35:45 DEBUG] [cli:119][39m Using settings file '/Users/collinsorighose/.chaostoolkit/settings.yaml'
[36m[2023-08-29 15:35:45 DEBUG] [settings:30][39m The Chaos Toolkit settings file could not be found at '/Users/collinsorighose/.chaostoolkit/settings.yaml'.
[36m[2023-08-29 15:35:45 DEBUG] [__init__:450][39m No controls to apply on 'loader'
[36m[2023-08-29 15:35:45 DEBUG] [__init__:450][39m No controls to apply on 'loader'
[36m[2023-08-29 15:35:45 DEBUG] [caching:24][39m Building activity cache...
[36m[2023-08-29 15:35:45 DEBUG] [caching:35][39m Cached 1 activities
[32m[2023-08-29 15:35:45 INFO] [experiment:58][39m Validating the experiment's syntax
[36m[2023-08-29 15:35:45 DEBUG] [configuration:63][39m Loading configuration...
[36m[2023-08-29 15:35:45 DEBUG] [secret:78][39m Loading secrets...
[36m[2023-08-29 15:35:45 DEBUG] [secret:103][39m Done loading secrets
[32m[2023-08-29 15:35:45 INFO] [experiment:109][39m Experiment looks valid
[36m[2023-08-29 15:35:45 DEBUG] [caching:42][39m Clearing activities cache
[36m[2023-08-29 15:35:45 DEBUG] [cli:314][39m Runtime strategies: hypothesis - default / rollbacks - default
[36m[2023-08-29 15:35:45 DEBUG] [caching:24][39m Building activity cache...
[36m[2023-08-29 15:35:45 DEBUG] [caching:35][39m Cached 1 activities
[36m[2023-08-29 15:35:45 DEBUG] [configuration:63][39m Loading configuration...
[36m[2023-08-29 15:35:45 DEBUG] [secret:78][39m Loading secrets...
[36m[2023-08-29 15:35:45 DEBUG] [secret:103][39m Done loading secrets
[36m[2023-08-29 15:35:45 DEBUG] [configuration:160][39m Loading dynamic configuration...
[32m[2023-08-29 15:35:45 INFO] [run:369][39m Running experiment: create SSM document
[36m[2023-08-29 15:35:45 DEBUG] [__init__:64][39m Initializing controls
[32m[2023-08-29 15:35:45 INFO] [run:396][39m Steady-state strategy: default
[32m[2023-08-29 15:35:45 INFO] [run:400][39m Rollbacks strategy: default
[32m[2023-08-29 15:35:45 INFO] [run:408][39m No steady state hypothesis defined. That's ok, just exploring.
[36m[2023-08-29 15:35:45 DEBUG] [__init__:450][39m No controls to apply on 'experiment'
[32m[2023-08-29 15:35:45 INFO] [run:684][39m Playing your experiment's method now...
[36m[2023-08-29 15:35:45 DEBUG] [__init__:450][39m No controls to apply on 'method'
[36m[2023-08-29 15:35:45 DEBUG] [__init__:450][39m No controls to apply on 'activity'
[32m[2023-08-29 15:35:45 INFO] [activity:215][39m Action: create-document
[36m[2023-08-29 15:35:45 DEBUG] [python:33][39m Activity 'create-document' loaded from '/Users/collinsorighose/opt/anaconda3/envs/demo/lib/python3.11/site-packages/chaosaws/ssm/actions.py'
[36m[2023-08-29 15:35:45 DEBUG] [__init__:76][39m Using AWS region 'eu-west-2'
[36m[2023-08-29 15:35:45 DEBUG] [__init__:85][39m Client will be using profile 'default' from boto3 session
[36m[2023-08-29 15:35:46 DEBUG] [activity:294][39m Activity failed
    Traceback (most recent call last):
      File "/Users/collinsorighose/opt/anaconda3/envs/demo/lib/python3.11/site-packages/chaosaws/ssm/actions.py", line 39, in create_document
        return client.create_document(
               ^^^^^^^^^^^^^^^^^^^^^^^
      File "/Users/collinsorighose/opt/anaconda3/envs/demo/lib/python3.11/site-packages/botocore/client.py", line 530, in _api_call
        return self._make_api_call(operation_name, kwargs)
               ^^^^^^^^^^^^^^^^^^^^^^^^^^^^^^^^^^^^^^^^^^^
      File "/Users/collinsorighose/opt/anaconda3/envs/demo/lib/python3.11/site-packages/botocore/client.py", line 960, in _make_api_call
        raise error_class(parsed_response, operation_name)
    botocore.exceptions.ClientError: An error occurred (ValidationException) when calling the CreateDocument operation: 3 validation errors detected: Value at 'documentType' failed to satisfy constraint: Member is not a valid documentType; Value at 'versionName' failed to satisfy constraint: Member must satisfy regular expression pattern: ^[a-zA-Z0-9_\-.]{1,128}$; Value at 'documentFormat' failed to satisfy constraint: Member must satisfy enum value set: [YAML, JSON, TEXT]
    
    During handling of the above exception, another exception occurred:
    
    Traceback (most recent call last):
      File "/Users/collinsorighose/opt/anaconda3/envs/demo/lib/python3.11/site-packages/chaoslib/provider/python.py", line 56, in run_python_activity
        return func(**arguments)
               ^^^^^^^^^^^^^^^^^
      File "/Users/collinsorighose/opt/anaconda3/envs/demo/lib/python3.11/site-packages/chaosaws/ssm/actions.py", line 47, in create_document
        raise ActivityFailed(
    chaoslib.exceptions.ActivityFailed: Failed to create document 'chaos-ssm-doc': '3 validation errors detected: Value at 'documentType' failed to satisfy constraint: Member is not a valid documentType; Value at 'versionName' failed to satisfy constraint: Member must satisfy regular expression pattern: ^[a-zA-Z0-9_\-.]{1,128}$; Value at 'documentFormat' failed to satisfy constraint: Member must satisfy enum value set: [YAML, JSON, TEXT]'
    
    During handling of the above exception, another exception occurred:
    
    Traceback (most recent call last):
      File "/Users/collinsorighose/opt/anaconda3/envs/demo/lib/python3.11/site-packages/chaoslib/activity.py", line 287, in run_activity
        result = run_python_activity(activity, configuration, secrets)
                 ^^^^^^^^^^^^^^^^^^^^^^^^^^^^^^^^^^^^^^^^^^^^^^^^^^^^^
      File "/Users/collinsorighose/opt/anaconda3/envs/demo/lib/python3.11/site-packages/chaoslib/provider/python.py", line 58, in run_python_activity
        raise ActivityFailed(
      File "/Users/collinsorighose/opt/anaconda3/envs/demo/lib/python3.11/site-packages/chaoslib/provider/python.py", line 56, in run_python_activity
        return func(**arguments)
               ^^^^^^^^^^^^^^^^^
      File "/Users/collinsorighose/opt/anaconda3/envs/demo/lib/python3.11/site-packages/chaosaws/ssm/actions.py", line 47, in create_document
        raise ActivityFailed(
    chaoslib.exceptions.ActivityFailed: chaoslib.exceptions.ActivityFailed: Failed to create document 'chaos-ssm-doc': '3 validation errors detected: Value at 'documentType' failed to satisfy constraint: Member is not a valid documentType; Value at 'versionName' failed to satisfy constraint: Member must satisfy regular expression pattern: ^[a-zA-Z0-9_\-.]{1,128}$; Value at 'documentFormat' failed to satisfy constraint: Member must satisfy enum value set: [YAML, JSON, TEXT]'
[31m[2023-08-29 15:35:46 ERROR] [activity:245][39m   => failed: chaoslib.exceptions.ActivityFailed: Failed to create document 'chaos-ssm-doc': '3 validation errors detected: Value at 'documentType' failed to satisfy constraint: Member is not a valid documentType; Value at 'versionName' failed to satisfy constraint: Member must satisfy regular expression pattern: ^[a-zA-Z0-9_\-.]{1,128}$; Value at 'documentFormat' failed to satisfy constraint: Member must satisfy enum value set: [YAML, JSON, TEXT]'
[36m[2023-08-29 15:35:46 DEBUG] [__init__:450][39m No controls to apply on 'activity'
[36m[2023-08-29 15:35:46 DEBUG] [__init__:450][39m No controls to apply on 'method'
[32m[2023-08-29 15:35:46 INFO] [run:964][39m Let's rollback...
[36m[2023-08-29 15:35:46 DEBUG] [__init__:450][39m No controls to apply on 'rollback'
[32m[2023-08-29 15:35:46 INFO] [rollback:31][39m No declared rollbacks, let's move on.
[36m[2023-08-29 15:35:46 DEBUG] [__init__:450][39m No controls to apply on 'rollback'
[32m[2023-08-29 15:35:46 INFO] [run:515][39m Experiment ended with status: completed
[36m[2023-08-29 15:35:46 DEBUG] [__init__:450][39m No controls to apply on 'experiment'
[36m[2023-08-29 15:35:46 DEBUG] [__init__:103][39m Cleaning up controls
[36m[2023-08-29 15:35:46 DEBUG] [caching:42][39m Clearing activities cache
